<?xml version="1.0"?>
<robot name="usv" xmlns:xacro="http://www.ros.org/wiki/xacro">
    <xacro:arg name="prefix" default="usv"/>

  <link name="$(arg prefix)/base_link">
    <visual>
    <geometry>
        <mesh filename="file://$(find ecn_usv)/urdf/hull.dae"  scale=".2 .2 .2"/>
      </geometry>
      <origin rpy="0 0 ${pi/2}"/>
    </visual>
  </link>

    <link name="$(arg prefix)/support">
    <visual>
    <geometry>
        <mesh filename="file://$(find ecn_usv)/urdf/support.dae"  scale=".2 .2 .2"/>
      </geometry>
    </visual>
  </link>

    <link name="$(arg prefix)/blades">
    <visual>
    <geometry>
        <mesh filename="file://$(find ecn_usv)/urdf/blades.dae" scale=".2 .2 .2"/>
    </geometry>
    </visual>
  </link>

  <joint name="support" type="revolute">
    <parent link="$(arg prefix)/base_link"/>
    <child link="$(arg prefix)/support"/>
    <axis xyz="0 0 1"/>
    <origin xyz="-0.2 0 6." rpy="0 0 ${pi/2}"/>
    <limit lower="-2" upper="2" velocity="20" effort="100"/>
  </joint>

  <joint name="blades" type="continuous">
    <parent link="$(arg prefix)/support"/>
    <child link="$(arg prefix)/blades"/>
    <axis xyz="0 1 0"/>
    <origin xyz="0 0.6 1.88"/>
  </joint>

</robot>
